Workbook
Name closeaverage: SalespersonData!$H$3
Name contractaverage: SalespersonData!$H$2

Sheet SalespersonData
A1: Date | B1: Salesperson | C1: Contracts Sold | D1: Close Rate
A2: 41275 | B2: Aiden Morris | C2: 13 | D2: 0.55
A3: 41275 | B3: Audrey Baker | C3: 11 | D3: 0.3
A4: 41275 | B4: Constantine Eager | C4: 9 | D4: 0.36
A5: 41275 | B5: Francis Martineau | C5: 11 | D5: 0.22
A6: 41275 | B6: George O'Malley | C6: 14 | D6: 0.33
A7: 41275 | B7: Ken Railings | C7: 3 | D7: 0.2
A8: 41275 | B8: Laura Yeager | C8: 14 | D8: 0.35
A9: 41275 | B9: Marianne James | C9: 7 | D9: 0.45
A10: 41275 | B10: Michael Smith | C10: 2 | D10: 0.13
A11: 41275 | B11: Priscilla Taylor | C11: 15 | D11: 0.48
A12: 41365 | B12: Aiden Morris | C12: 11 | D12: 0.48333333
A13: 41365 | B13: Audrey Baker | C13: 12 | D13: 0.3
... A161: 42644 | B161: Priscilla Taylor | C161: 16 | D161: 0.51

Sheet SalesData1
A1: Date | B1: Country | C1: City | D1: Region | E1: Segment | F1: Sales | G1: Cost
A2: 41275 | B2: Cote d'Ivoire | C2: Abidjan | D2: Western | E2: Commercial | F2: 656.96 | G2: 650.39
A3: 41275 | B3: Madagascar | C3: Antananarivo | D3: Eastern | E3: Public | F3: 875.94 | G3: 946.02
A4: 41275 | B4: Rwanda | C4: Kigali | D4: Eastern | E4: Public | F4: 258.35 | G4: 240.27
A5: 41275 | B5: Zimbabwe | C5: Harare | D5: Eastern | E5: Residential | F5: 875.62 | G5: 910.64
A6: 41276 | B6: Ethiopia | C6: Addis Ababa | D6: Eastern | E6: Residential | F6: 509.93 | G6: 499.73
A7: 41277 | B7: Chad | C7: N'Djamena | D7: Middle | E7: Commercial | F7: 443.13 | G7: 438.7
A8: 41277 | B8: Malawi | C8: Blantyre | D8: Eastern | E8: Residential | F8: 651.78 | G8: 632.23
A9: 41277 | B9: Mauritius | C9: Port Louis | D9: Eastern | E9: Public | F9: 896.64 | G9: 959.4
A10: 41278 | B10: Sao Tome and Principe | C10: Sao Tome | D10: Middle | E10: Commercial | F10: 226.92 | G10: 213.3
A11: 41279 | B11: Cameroon | C11: Yaoundé | D11: Middle | E11: Public | F11: 77.41 | G11: 73.54
A12: 41279 | B12: Cote d'Ivoire | C12: Yamoussoukro | D12: Western | E12: Public | F12: 263.65 | G12: 253.1
A13: 41279 | B13: Nigeria | C13: Lagos | D13: Western | E13: Residential | F13: 950.83 | G13: 998.37
... A792: 42364 | B792: Congo | C792: Brazzaville | D792: Middle | E792: Commercial | F792: 498.92 | G792: 503.91

Sheet SalesData1_pivot
I11: 年(Date) | J11: 2013年
B13: 行标签 | C13: 收入 | D13: 收入排序 | E13: 收入占比 | I13: 行标签 | J13: 收入 | K13: 求和项:利润 | L13: 利润排序 | M13: 利润占比
B14: 2013年 | C14: 24326.73 | E14: 0.35779181 | I14: Algeria | J14: 2867.75 | K14: -19.72 | L14: 35 | M14: -0.021236041
B15: Democratic Republic of the Congo | C15: 5856.15 | D15: 3 | E15: 0.086130873 | I15: Angola | J15: 1451.46 | K15: 123.82 | L15: 5 | M15: 0.13333908
B16: Nigeria | C16: 9327.34 | D16: 1 | E16: 0.13718432 | I16: Benin | J16: 5108.14 | K16: 98.21 | L16: 9 | M16: 0.10576022
B17: South Africa | C17: 9143.24 | D17: 2 | E17: 0.13447662 | I17: Botswana | J17: 2603.16 | K17: 170.67 | L17: 1 | M17: 0.18379083
B18: 2014年 | C18: 23437.21 | E18: 0.34470896 | I18: Burkina Faso | J18: 2335.56 | K18: -28.49 | L18: 41 | M18: -0.030680264
B19: Democratic Republic of the Congo | C19: 6177.6 | D19: 3 | E19: 0.090858683 | I19: Burundi | J19: 1052.36 | K19: -3.46 | L19: 28 | M19: -0.0037259991
B20: Nigeria | C20: 6618.11 | D20: 2 | E20: 0.097337601 | I20: Cameroon | J20: 4406.54 | K20: 41.84 | L20: 16 | M20: 0.04505659
B21: South Africa | C21: 10641.5 | D21: 1 | E21: 0.15651267 | I21: Central African Republic | J21: 1865.14 | K21: 66.69 | L21: 12 | M21: 0.071817017
B22: 2015年 | C22: 20227.36 | E22: 0.29749924 | I22: Chad | J22: 1267.88 | K22: 33.23 | L22: 19 | M22: 0.035784667
B23: Cote d'Ivoire | C23: 5435.86 | D23: 3 | E23: 0.079949346 | I23: Congo | J23: 2464.99 | K23: -23.24 | L23: 36 | M23: -0.025026653
B24: Nigeria | C24: 5847.1 | D24: 2 | E24: 0.085997767 | I24: Cote d'Ivoire | J24: 4623.18 | K24: -143.83 | L24: 51 | M24: -0.15488741
B25: South Africa | C25: 8944.4 | D25: 1 | E25: 0.13155213 | I25: Democratic Republic of the Congo | J25: 5856.15 | K25: 132.56 | L25: 4 | M25: 0.14275099
B26: 总计 | C26: 67991.3 | E26: 1 | I26: Djibouti | J26: 3005.07 | K26: -12.66 | L26: 32 | M26: -0.01363328
I27: Egypt | J27: 2644.26 | K27: 141.04 | L27: 3 | M27: 0.15188292
I28: Equatorial Guinea | J28: 3030.3 | K28: -0.21 | L28: 27 | M28: -0.00022614445
I29: Eritrea | J29: 2001.2 | K29: -14.16 | L29: 33 | M29: -0.015248597
I30: Ethiopia | J30: 1515.05 | K30: -6.27 | L30: 29 | M30: -0.0067520272
I31: Gabon | J31: 3802.02 | K31: 1.12 | L31: 26 | M31: 0.0012061037
I32: Ghana | J32: 3605.45 | K32: -24.84 | L32: 37 | M32: -0.026749658
I33: Guinea | J33: 1317.22 | K33: 27.99 | L33: 20 | M33: 0.030141825
I34: Guinea-Bissau | J34: 2182.5 | K34: 118.06 | L34: 6 | M34: 0.12713626
I35: Kenya | J35: 2310.07 | K35: -30.18 | L35: 43 | M35: -0.032500188
I36: Lesotho | J36: 1762.79 | K36: 104.22 | L36: 8 | M36: 0.11223226
I37: Liberia | J37: 1796.75 | K37: -75.31 | L37: 48 | M37: -0.081099708
I38: Libya | J38: 2313.13 | K38: 40.17 | L38: 17 | M38: 0.043258203
... I65: Zimbabwe | J65: 1950.22 | K65: -75.17 | L65: 47 | M65: -0.080948945
I66: 总计 | J66: 137717.57 | K66: 928.61 | M66: 1

Sheet SalesData 2
A1: Date | B1: Country | C1: City | D1: Region | E1: Segment | F1: Sales | G1: Cost | H1: Profit
A2: 41275 | B2: Cote d'Ivoire | C2: Abidjan | D2: Western | E2: Commercial | F2: 656.96 | G2: 650.39 | H2: ='SalesData 2'!$F2-'SalesData 2'!$G2 -> 6.57
A3: 41275 | B3: Madagascar | C3: Antananarivo | D3: Eastern | E3: Public | F3: 875.94 | G3: 946.02 | H3: ='SalesData 2'!$F3-'SalesData 2'!$G3 -> -70.08
A4: 41275 | B4: Rwanda | C4: Kigali | D4: Eastern | E4: Public | F4: 258.35 | G4: 240.27 | H4: ='SalesData 2'!$F4-'SalesData 2'!$G4 -> 18.08
A5: 41275 | B5: Zimbabwe | C5: Harare | D5: Eastern | E5: Residential | F5: 875.62 | G5: 910.64 | H5: ='SalesData 2'!$F5-'SalesData 2'!$G5 -> -35.02
A6: 41276 | B6: Ethiopia | C6: Addis Ababa | D6: Eastern | E6: Residential | F6: 509.93 | G6: 499.73 | H6: ='SalesData 2'!$F6-'SalesData 2'!$G6 -> 10.2
A7: 41277 | B7: Chad | C7: N'Djamena | D7: Middle | E7: Commercial | F7: 443.13 | G7: 438.7 | H7: ='SalesData 2'!$F7-'SalesData 2'!$G7 -> 4.43
A8: 41277 | B8: Malawi | C8: Blantyre | D8: Eastern | E8: Residential | F8: 651.78 | G8: 632.23 | H8: ='SalesData 2'!$F8-'SalesData 2'!$G8 -> 19.55
A9: 41277 | B9: Mauritius | C9: Port Louis | D9: Eastern | E9: Public | F9: 896.64 | G9: 959.4 | H9: ='SalesData 2'!$F9-'SalesData 2'!$G9 -> -62.76
A10: 41278 | B10: Sao Tome and Principe | C10: Sao Tome | D10: Middle | E10: Commercial | F10: 226.92 | G10: 213.3 | H10: ='SalesData 2'!$F10-'SalesData 2'!$G10 -> 13.62
A11: 41279 | B11: Cameroon | C11: Yaoundé | D11: Middle | E11: Public | F11: 77.41 | G11: 73.54 | H11: ='SalesData 2'!$F11-'SalesData 2'!$G11 -> 3.87
A12: 41279 | B12: Cote d'Ivoire | C12: Yamoussoukro | D12: Western | E12: Public | F12: 263.65 | G12: 253.1 | H12: ='SalesData 2'!$F12-'SalesData 2'!$G12 -> 10.55
A13: 41279 | B13: Nigeria | C13: Lagos | D13: Western | E13: Residential | F13: 950.83 | G13: 998.37 | H13: ='SalesData 2'!$F13-'SalesData 2'!$G13 -> -47.54
... A73: 41323 | B73: Cote d'Ivoire | C73: Yamoussoukro | D73: Western | E73: Commercial | F73: 436.3 | G73: 453.75 | H73: ='SalesData 2'!$F73-'SalesData 2'!$G73 -> -17.45
A74: 41323 | B74: United Republic of Tanzania | C74: Dar es Salaam | D74: Eastern | E74: Commercial | F74: 401.85 | G74: 397.83 | H74: ='SalesData 2'!$F74-'SalesData 2'!G$74 -> 4.02
A75: 41324 | B75: Democratic Republic of the Congo | C75: Mbuji-Mayi | D75: Middle | E75: Residential | F75: 246.28 | G75: 233.97 | H75: ='SalesData 2'!$F75-'SalesData 2'!$G75 -> 12.31
A76: 41325 | B76: Equatorial Guinea | C76: Malabo | D76: Middle | E76: Residential | F76: 996.56 | G76: 986.59 | H76: ='SalesData 2'!$F76-'SalesData 2'!$G76 -> 9.97
A77: 41326 | B77: Sudan | C77: Khartoum | D77: Northern | E77: Public | F77: 99.2 | G77: 91.26 | H77: ='SalesData 2'!$F77-'SalesData 2'!$G77 -> 7.94
A78: 41330 | B78: Senegal | C78: Dakar | D78: Western | E78: Residential | F78: 193.94 | G78: 205.58 | H78: ='SalesData 2'!$F78-'SalesData 2'!$G78 -> -11.64
A79: 41331 | B79: Nigeria | C79: Lagos | D79: Western | E79: Residential | F79: 316.67 | G79: 329.34 | H79: ='SalesData 2'!$F79-'SalesData 2'!$G79 -> -12.67
A80: 41332 | B80: Uganda | C80: Kampala | D80: Eastern | E80: Residential | F80: 983.55 | G80: 963.88 | H80: ='SalesData 2'!$F80-'SalesData 2'!$G80 -> 19.67
A81: 41333 | B81: Eritrea | C81: Asmara | D81: Eastern | E81: Public | F81: 196.57 | G81: 182.81 | H81: ='SalesData 2'!$F81-'SalesData 2'!$G81 -> 13.76
A82: 41333 | B82: Libya | C82: Tripoli | D82: Northern | E82: Commercial | F82: 258.25 | G82: 273.75 | H82: ='SalesData 2'!$F82-'SalesData 2'!$G82 -> -15.5
A83: 41335 | B83: Burundi | C83: Bujumbura | D83: Eastern | E83: Public | F83: 428.05 | G83: 432.33 | H83: ='SalesData 2'!$F83-'SalesData 2'!$G83 -> -4.28
A84: 41336 | B84: Gabon | C84: Libreville | D84: Middle | E84: Public | F84: 952.76 | G84: 914.65 | H84: ='SalesData 2'!$F84-'SalesData 2'!$G84 -> 38.11
A85: 41336 | B85: Zimbabwe | C85: Harare | D85: Eastern | E85: Residential | F85: 391.72 | G85: 395.64 | H85: ='SalesData 2'!$F85-'SalesData 2'!$G85 -> -3.92
A86: 41338 | B86: Central African Republic | C86: Bangui | D86: Middle | E86: Residential | F86: 363.3 | G86: 356.03 | H86: ='SalesData 2'!$F86-'SalesData 2'!$G86 -> 7.27
... A792: 42364 | B792: Congo | C792: Brazzaville | D792: Middle | E792: Commercial | F792: 498.92 | G792: 503.91 | H792: ='SalesData 2'!$F792-'SalesData 2'!$G792 -> -4.99

Sheet SalesData2_pivot
B17: 行标签 | C17: 求和项:Profit | D17: 利润占比 | E17: 月利润占比年 | F17: 同比2013增长量 | G17: 同比2013增长率 | H17: 同比上一年增长量 | I17: 同比上一年增长率 | J17: 环比上月增长量 | K17: 环比1月增长量 | L17: 月累计值 | M17: 月累计百分比
B18: 2013年 | C18: 928.61 | D18: 0.23541058 | E18: 1
B19: 1月 | C19: 262.78 | D19: 0.066616979 | E19: 0.28298209 | L19: 262.78 | M19: 0.28298209
B20: 2月 | C20: 28.7 | D20: 0.0072756956 | E20: 0.030906409 | J20: -234.08 | K20: -234.08 | L20: 291.48 | M20: 0.3138885
B21: 3月 | C21: 183.5 | D21: 0.04651882 | E21: 0.19760718 | J21: 154.8 | K21: -79.28 | L21: 474.98 | M21: 0.51149568
B22: 4月 | C22: 100.49 | D22: 0.025475075 | E22: 0.1082155 | J22: -83.01 | K22: -162.29 | L22: 575.47 | M22: 0.61971118
B23: 5月 | C23: 168.7 | D23: 0.042766894 | E23: 0.18166938 | J23: 68.21 | K23: -94.08 | L23: 744.17 | M23: 0.80138056
B24: 6月 | C24: 139.07 | D24: 0.035255435 | E24: 0.14976147 | J24: -29.63 | K24: -123.71 | L24: 883.24 | M24: 0.95114203
B25: 7月 | C25: 99.95 | D25: 0.02533818 | E25: 0.10763399 | J25: -39.12 | K25: -162.83 | L25: 983.19 | M25: 1.058776
B26: 8月 | C26: -53.6 | D26: -0.013588059 | E26: -0.057720679 | J26: -153.55 | K26: -316.38 | L26: 929.59 | M26: 1.0010553
B27: 9月 | C27: 0.51 | D27: 0.00012928936 | E27: 0.00054920796 | J27: 54.11 | K27: -262.27 | L27: 930.1 | M27: 1.0016045
B28: 10月 | C28: -26.1 | D28: -0.0066165734 | E28: -0.028106525 | J28: -26.61 | K28: -288.88 | L28: 904 | M28: 0.97349802
B29: 11月 | C29: -88.42 | D29: -0.022415227 | E29: -0.095217583 | J29: -62.32 | K29: -351.2 | L29: 815.58 | M29: 0.87828044
B30: 12月 | C30: 113.03 | D30: 0.028654072 | E30: 0.12171956 | J30: 201.45 | K30: -149.75 | L30: 928.61 | M30: 1
B31: 2014年 | C31: 1968.91 | D31: 0.49913554 | E31: 1 | F31: 1040.3 | G31: 1.1202765 | H31: 1040.3 | I31: 1.1202765
B32: 1月 | C32: 440.92 | D32: 0.11177699 | E32: 0.22394117 | F32: 178.14 | G32: 0.67790547 | H32: 178.14 | I32: 0.67790547 | L32: 440.92 | M32: 0.22394117
B33: 2月 | C33: 114.16 | D33: 0.028940537 | E33: 0.05798132 | F33: 85.46 | G33: 2.9777003 | H33: 85.46 | I33: 2.9777003 | J33: -326.76 | K33: -326.76 | L33: 555.08 | M33: 0.28192249
B34: 3月 | C34: 201.59 | D34: 0.05110479 | E34: 0.1023866 | F34: 18.09 | G34: 0.098583106 | H34: 18.09 | I34: 0.098583106 | J34: 87.43 | K34: -239.33 | L34: 756.67 | M34: 0.38430908
B35: 4月 | C35: 17.98 | D35: 0.0045580839 | E35: 0.0091319563 | F35: -82.51 | G35: -0.82107672 | H35: -82.51 | I35: -0.82107672 | J35: -183.61 | K35: -422.94 | L35: 774.65 | M35: 0.39344104
B36: 5月 | C36: 349.2 | D36: 0.088525189 | E36: 0.17735701 | F36: 180.5 | G36: 1.0699467 | H36: 180.5 | I36: 1.0699467 | J36: 331.22 | K36: -91.72 | L36: 1123.85 | M36: 0.57079806
B37: 6月 | C37: 268.52 | D37: 0.068072118 | E37: 0.13638003 | F37: 129.45 | G37: 0.9308262 | H37: 129.45 | I37: 0.9308262 | J37: -80.68 | K37: -172.4 | L37: 1392.37 | M37: 0.70717808
B38: 7月 | C38: 48.06 | D38: 0.012183621 | E38: 0.024409445 | F38: -51.89 | G38: -0.51915958 | H38: -51.89 | I38: -0.51915958 | J38: -220.46 | K38: -392.86 | L38: 1440.43 | M38: 0.73158753
B39: 8月 | C39: -3.54 | D39: -0.0008974203 | E39: -0.0017979491 | F39: 50.06 | G39: -0.93395522 | H39: 50.06 | I39: -0.93395522 | J39: -51.6 | K39: -444.46 | L39: 1436.89 | M39: 0.72978958
B40: 9月 | C40: 385.24 | D40: 0.097661637 | E40: 0.19566156 | F40: 384.73 | G40: 754.37255 | H40: 384.73 | I40: 754.37255 | J40: 388.78 | K40: -55.68 | L40: 1822.13 | M40: 0.92545114
B41: 10月 | C41: 159.79 | D41: 0.040508133 | E41: 0.081156579 | F41: 185.89 | G41: -7.1222222 | H41: 185.89 | I41: -7.1222222 | J41: -225.45 | K41: -281.13 | L41: 1981.92 | M41: 1.0066077
B42: 11月 | C42: -34.29 | D42: -0.0086928085 | E42: -0.017415727 | F42: 54.13 | G42: -0.61219181 | H42: 54.13 | I42: -0.61219181 | J42: -194.08 | K42: -475.21 | L42: 1947.63 | M42: 0.98919199
B43: 12月 | C43: 21.28 | D43: 0.0053946621 | E43: 0.010808011 | F43: -91.75 | G43: -0.8117314 | H43: -91.75 | I43: -0.8117314 | J43: 55.57 | K43: -419.64 | L43: 1968.91 | M43: 1
B44: 2015年 | C44: 1047.12 | D44: 0.26545388 | E44: 1 | F44: 118.51 | G44: 0.12762085 | H44: -921.79 | I44: -0.46817275
B45: 1月 | C45: 696.69 | D45: 0.17661688 | E45: 0.66533922 | F45: 433.91 | G45: 1.6512292 | H45: 255.77 | I45: 0.58008255 | L45: 696.69 | M45: 0.66533922
B46: 2月 | C46: -17.15 | D46: -0.0043476718 | E46: -0.016378257 | F46: -45.85 | G46: -1.597561 | H46: -131.31 | I46: -1.1502278 | J46: -713.84 | K46: -713.84 | L46: 679.54 | M46: 0.64896096
B47: 3月 | C47: -195.95 | D47: -0.049675002 | E47: -0.18713232 | F47: -379.45 | G47: -2.0678474 | H47: -397.54 | I47: -1.9720224 | J47: -178.8 | K47: -892.64 | L47: 483.59 | M47: 0.46182863
B48: 4月 | C48: -166.34 | D48: -0.042168614 | E48: -0.15885476 | F48: -266.83 | G48: -2.6552891 | H48: -184.32 | I48: -10.25139 | J48: 29.61 | K48: -863.03 | L48: 317.25 | M48: 0.30297387
B49: 5月 | C49: -154.4 | D49: -0.039141721 | E49: -0.14745206 | F49: -323.1 | G49: -1.9152341 | H49: -503.6 | I49: -1.4421535 | J49: 11.94 | K49: -851.09 | L49: 162.85 | M49: 0.15552181
B50: 6月 | C50: 135.84 | D50: 0.034436603 | E50: 0.12972725 | F50: -3.23 | G50: -0.023225714 | H50: -132.68 | I50: -0.49411589 | J50: 290.24 | K50: -560.85 | L50: 298.69 | M50: 0.28524906
B51: 7月 | C51: 230.03 | D51: 0.058314574 | E51: 0.21967874 | F51: 130.08 | G51: 1.3014507 | H51: 181.97 | I51: 3.7863088 | J51: 94.19 | K51: -466.66 | L51: 528.72 | M51: 0.5049278
B52: 8月 | C52: 137.58 | D52: 0.034877707 | E52: 0.13138895 | F52: 191.18 | G52: -3.566791 | H52: 141.12 | I52: -39.864407 | J52: -92.45 | K52: -559.11 | L52: 666.3 | M52: 0.63631675
B53: 9月 | C53: 147.34 | D53: 0.037351951 | E53: 0.14070976 | F53: 146.83 | G53: 287.90196 | H53: -237.9 | I53: -0.61753712 | J53: 9.76 | K53: -549.35 | L53: 813.64 | M53: 0.77702651
B54: 10月 | C54: 30.72 | D54: 0.0077877829 | E54: 0.029337612 | F54: 56.82 | G54: -2.1770115 | H54: -129.07 | I54: -0.80774767 | J54: -116.62 | K54: -665.97 | L54: 844.36 | M54: 0.80636412
B55: 11月 | C55: 136.96 | D55: 0.034720532 | E55: 0.13079685 | F55: 225.38 | G55: -2.5489708 | H55: 171.25 | I55: -4.9941674 | J55: 106.24 | K55: -559.73 | L55: 981.32 | M55: 0.93716097
B56: 12月 | C56: 65.8 | D56: 0.016680863 | E56: 0.062839025 | F56: -47.23 | G56: -0.41785367 | H56: 44.52 | I56: 2.0921053 | J56: -71.16 | K56: -630.89 | L56: 1047.12 | M56: 1
...

Sheet SalesData_2016
A1: Date | B1: Country | C1: City | D1: Region | E1: Segment | F1: Sales | G1: Cost | H1: Profit
A2: 42370 | B2: Ghana | C2: Accra | D2: Western | E2: Residential | F2: 527.43 | G2: 527.43 | H2: 0
A3: 42370 | B3: Malawi | C3: Lilongwe | D3: Eastern | E3: Public | F3: 162.93 | G3: 174.34 | H3: -11.41
A4: 42371 | B4: Benin | C4: Porto-Novo | D4: Western | E4: Residential | F4: 186.23 | G4: 171.33 | H4: 14.9
A5: 42371 | B5: Nigeria | C5: Lagos | D5: Western | E5: Residential | F5: 279.55 | G5: 257.19 | H5: 22.36
A6: 42371 | B6: Sao Tome and Principe | C6: Sao Tome | D6: Middle | E6: Residential | F6: 810.6 | G6: 770.07 | H6: 40.53
A7: 42372 | B7: Angola | C7: Luanda | D7: Middle | E7: Residential | F7: 460.06 | G7: 418.65 | H7: 41.41
A8: 42372 | B8: Madagascar | C8: Antananarivo | D8: Eastern | E8: Public | F8: 335.21 | G8: 345.27 | H8: -10.06
A9: 42373 | B9: Ghana | C9: Kumasi | D9: Western | E9: Commercial | F9: 123.38 | G9: 129.55 | H9: -6.17
A10: 42373 | B10: Guinea-Bissau | C10: Bissau | D10: Western | E10: Commercial | F10: 153.68 | G10: 141.39 | H10: 12.29
A11: 42373 | B11: Rwanda | C11: Kigali | D11: Eastern | E11: Public | F11: 3.1 | G11: 3.01 | H11: 0.09
A12: 42373 | B12: Zimbabwe | C12: Harare | D12: Eastern | E12: Residential | F12: 449.7 | G12: 449.7 | H12: 0
A13: 42374 | B13: Benin | C13: Cotonou | D13: Western | E13: Commercial | F13: 389.61 | G13: 374.03 | H13: 15.58
... A265: 42732 | B265: United Republic of Tanzania | C265: Dar es Salaam | D265: Eastern | E265: Residential | F265: 859.82 | G265: 920.01 | H265: -60.19
